Loading rhel8/default-amp
  Loading requirement: dot rhel8/slurm singularity/current rhel8/global
    cuda/11.4 libpciaccess/0.16/gcc-9.4.0-6fonbj6
    libiconv/1.16/gcc-9.4.0-ahebbov libxml2/2.9.12/gcc-9.4.0-gnknt5e
    ncurses/6.2/gcc-9.4.0-aiirok7 hwloc/2.5.0/gcc-9.4.0-7sqomga
    libevent/2.1.12/gcc-9.4.0-hgny7cm numactl/2.0.14/gcc-9.4.0-52dwc6n
    cuda/11.4.0/gcc-9.4.0-3hnxhjt gdrcopy/2.2/gcc-9.4.0-e4igtfp
    knem/1.1.4/gcc-9.4.0-bpbxgva libnl/3.3.0/gcc-9.4.0-whwhrwb
    rdma-core/34.0/gcc-9.4.0-5eo5n2u ucx/1.11.1/gcc-9.4.0-lktqyl4
    openmpi/4.1.1/gcc-9.4.0-epagguv
Changed directory to /rds/user/tdb47/hpc-work/planning/thinker_private_planning/probing.

JobID: 58640748
======
Time: Sat Aug 10 10:19:16 BST 2024
Running on master node: gpu-q-74
Current directory: /rds/user/tdb47/hpc-work/planning/thinker_private_planning/probing

Nodes allocated:
================
gpu-q-74

numtasks=1, numnodes=1, mpi_tasks_per_node=1 (OMP_NUM_THREADS=1)

Executing command:
==================
python run_agent_interv_exps.py 


Initializing env 0 with device cpu
Init. environment with obs space [91mBox(0, 1, (7, 8, 8), uint8)[0m and action space [91mDiscrete(5)[0m
========================================= layer=0, alpha=0.25, interv=0, seed=0==================================
terminate called after throwing an instance of 'std::runtime_error'
  what():  box_left must be equal to 4 (room_id: 0)
Traceback (most recent call last):
  File "/rds/user/tdb47/hpc-work/planning/thinker_private_planning/probing/run_agent_interv_exps.py", line 377, in <module>
    state = env.reset()
  File "/rds/user/tdb47/hpc-work/planning/thinker_private_planning/thinker/thinker/main.py", line 411, in reset
    state = self.env.reset(self.model_net)
  File "/rds/user/tdb47/hpc-work/planning/thinker_private_planning/thinker/thinker/wrapper.py", line 114, in reset
    state = self.env.reset(model_net)
  File "/rds/user/tdb47/hpc-work/planning/thinker_private_planning/thinker/thinker/wrapper.py", line 36, in reset
    obs = self.env.reset()
  File "/rds/user/tdb47/hpc-work/planning/thinker_private_planning/thinker/thinker/wrapper.py", line 947, in reset
    return self.env.reset(**kwargs)
  File "/rds/user/tdb47/hpc-work/planning/env/lib/python3.9/site-packages/gym/core.py", line 283, in reset
    return self.env.reset(**kwargs)
  File "/rds/user/tdb47/hpc-work/planning/thinker_private_planning/thinker/thinker/gym_add/vector_env.py", line 62, in reset
    return self.reset_wait()
  File "/rds/user/tdb47/hpc-work/planning/thinker_private_planning/thinker/thinker/gym_add/asyn_vector_env.py", line 237, in reset_wait
    results, successes = zip(*[pipe.recv() for pipe in rec_pipes])
  File "/rds/user/tdb47/hpc-work/planning/thinker_private_planning/thinker/thinker/gym_add/asyn_vector_env.py", line 237, in <listcomp>
    results, successes = zip(*[pipe.recv() for pipe in rec_pipes])
  File "/usr/local/software/spack/spack-git/opt/spack/linux-rhel7-broadwell/gcc-5.4.0/python-3.9.6-sbr552hsx3zanhgi3ekdjp4rsn6o6ejq/lib/python3.9/multiprocessing/connection.py", line 255, in recv
    buf = self._recv_bytes()
  File "/usr/local/software/spack/spack-git/opt/spack/linux-rhel7-broadwell/gcc-5.4.0/python-3.9.6-sbr552hsx3zanhgi3ekdjp4rsn6o6ejq/lib/python3.9/multiprocessing/connection.py", line 419, in _recv_bytes
    buf = self._recv(4)
  File "/usr/local/software/spack/spack-git/opt/spack/linux-rhel7-broadwell/gcc-5.4.0/python-3.9.6-sbr552hsx3zanhgi3ekdjp4rsn6o6ejq/lib/python3.9/multiprocessing/connection.py", line 388, in _recv
    raise EOFError
EOFError
/rds/user/tdb47/hpc-work/planning/thinker_private_planning/thinker/thinker/gym_add/asyn_vector_env.py:480: UserWarning: [33mWARN: Calling `close` while waiting for a pending call to `reset` to complete.[0m
Exception ignored in: <function VectorEnv.__del__ at 0x145d1f2fc820>
Traceback (most recent call last):
  File "/rds/user/tdb47/hpc-work/planning/thinker_private_planning/thinker/thinker/gym_add/vector_env.py", line 151, in __del__
  File "/rds/user/tdb47/hpc-work/planning/thinker_private_planning/thinker/thinker/gym_add/vector_env.py", line 133, in close
  File "/rds/user/tdb47/hpc-work/planning/thinker_private_planning/thinker/thinker/gym_add/asyn_vector_env.py", line 485, in close_extras
  File "/rds/user/tdb47/hpc-work/planning/thinker_private_planning/thinker/thinker/gym_add/asyn_vector_env.py", line 237, in reset_wait
  File "/rds/user/tdb47/hpc-work/planning/thinker_private_planning/thinker/thinker/gym_add/asyn_vector_env.py", line 237, in <listcomp>
  File "/usr/local/software/spack/spack-git/opt/spack/linux-rhel7-broadwell/gcc-5.4.0/python-3.9.6-sbr552hsx3zanhgi3ekdjp4rsn6o6ejq/lib/python3.9/multiprocessing/connection.py", line 255, in recv
  File "/usr/local/software/spack/spack-git/opt/spack/linux-rhel7-broadwell/gcc-5.4.0/python-3.9.6-sbr552hsx3zanhgi3ekdjp4rsn6o6ejq/lib/python3.9/multiprocessing/connection.py", line 419, in _recv_bytes
  File "/usr/local/software/spack/spack-git/opt/spack/linux-rhel7-broadwell/gcc-5.4.0/python-3.9.6-sbr552hsx3zanhgi3ekdjp4rsn6o6ejq/lib/python3.9/multiprocessing/connection.py", line 388, in _recv
EOFError: 
